#VRML_SIM R2025a utf8

# --------------------
# 1. World settings
# --------------------
WorldInfo {
  basicTimeStep 16
  title "Frog-inspired swimming robot - v17 half pool early turn"
}
Viewpoint {
  orientation 0.9481 0.3174 0 2.62
  position 0 11 18
}
Background {
  skyColor [ 0.95 0.96 0.98 ]
}
DirectionalLight {
  direction -0.25 -1.0 -0.35
  intensity 0.95
}
DirectionalLight {
  direction 0.35 -0.70 0.25
  intensity 0.35
}
Fog {
  color 0.86 0.92 0.98
  visibilityRange 55
}

# --------------------
# 2. Pool geometry
# --------------------
Solid {
  name "pool_floor"
  translation 0 -2.55 0
  children [
    Shape {
      appearance PBRAppearance {
        baseColor 0.10 0.24 0.46
        roughness 0.95
        metalness 0
      }
      geometry Box { size 32.0 0.30 21.0 }
    }
  ]
  boundingObject Box { size 32.0 0.30 21.0 }
}

Solid {
  name "pool_wall_north"
  translation 0 0 10.25
  children [
    Shape {
      appearance PBRAppearance {
        baseColor 0.78 0.81 0.86
        roughness 0.85
        metalness 0.02
      }
      geometry Box { size 32.0 5.0 0.50 }
    }
  ]
  boundingObject Box { size 32.0 5.0 0.50 }
}

Solid {
  name "pool_wall_south"
  translation 0 0 -10.25
  children [
    Shape {
      appearance PBRAppearance {
        baseColor 0.78 0.81 0.86
        roughness 0.85
        metalness 0.02
      }
      geometry Box { size 32.0 5.0 0.50 }
    }
  ]
  boundingObject Box { size 32.0 5.0 0.50 }
}

Solid {
  name "pool_wall_east"
  translation 15.75 0 0
  children [
    Shape {
      appearance PBRAppearance {
        baseColor 0.78 0.81 0.86
        roughness 0.85
        metalness 0.02
      }
      geometry Box { size 0.50 5.0 21.0 }
    }
  ]
  boundingObject Box { size 0.50 5.0 21.0 }
}

Solid {
  name "pool_wall_west"
  translation -15.75 0 0
  children [
    Shape {
      appearance PBRAppearance {
        baseColor 0.78 0.81 0.86
        roughness 0.85
        metalness 0.02
      }
      geometry Box { size 0.50 5.0 21.0 }
    }
  ]
  boundingObject Box { size 0.50 5.0 21.0 }
}

# --------------------
# 3. Water volume
# --------------------
DEF WATER Fluid {
  translation 0 -0.30 0
  name "water"
  density 1000
  viscosity 0.001
  streamVelocity 0 0 0
  boundingObject Box { size 30.8 4.40 19.8 }
}

Transform {
  translation 0 -0.30 0
  children [
    Shape {
      appearance PBRAppearance {
        baseColor 0.52 0.77 0.95
        roughness 0.08
        metalness 0
        transparency 0.72
      }
      geometry Box { size 30.8 4.40 19.8 }
    }
  ]
}

# --------------------
# 4. Frog robot
# --------------------
DEF FROG Robot {
  translation 0 0.66 -6.2
  rotation 1 0 0 1.5708
  name "frog_robot_v21"
  supervisor TRUE
  controller "frog_swim"
  immersionProperties [
    ImmersionProperties {
      fluidName "water"
      dragForceCoefficients 1.10 0.14 0.96
      viscousResistanceForceCoefficient 155
      viscousResistanceTorqueCoefficient 14
    }
  ]
  children [
    Transform {
      translation 0 0 0.050
      scale 0.82 1.75 0.72
      children [
        Shape {
          appearance PBRAppearance {
            baseColor 0.93 0.94 0.96
            roughness 0.80
            metalness 0.02
          }
          geometry Sphere {
            radius 0.170
          }
        }
      ]
    }
    Transform {
      translation 0 -0.010 0.086
      children [
        Shape {
          appearance PBRAppearance {
            baseColor 0.96 0.96 0.97
            roughness 0.72
            metalness 0.03
          }
          geometry Box {
            size 0.125 0.365 0.110
          }
        }
      ]
    }
    Transform {
      translation 0 0.205 0.086
      children [
        Shape {
          appearance PBRAppearance {
            baseColor 0.98 0.98 0.99
            roughness 0.72
            metalness 0.02
          }
          geometry Sphere {
            radius 0.064
          }
        }
      ]
    }
    Transform {
      translation -0.060 0.125 0.105
      children [
        Shape {
          appearance PBRAppearance {
            baseColor 0.28 0.28 0.28
            roughness 0.55
            metalness 0.02
          }
          geometry Sphere { radius 0.012 }
        }
      ]
    }
    Transform {
      translation 0.060 0.125 0.105
      children [
        Shape {
          appearance PBRAppearance {
            baseColor 0.28 0.28 0.28
            roughness 0.55
            metalness 0.02
          }
          geometry Sphere { radius 0.012 }
        }
      ]
    }

    HingeJoint {
      jointParameters HingeJointParameters {
        anchor -0.120 -0.150 0.085
        axis 0 0 1
      }
      device [
        RotationalMotor {
          name "left_hip"
          minPosition -1.20
          maxPosition 0.80
          maxTorque 260
          maxVelocity 4.0
        }
        PositionSensor {
          name "left_hip_sensor"
        }
      ]
      endPoint Solid {
        name "left_thigh"
        translation -0.120 -0.150 0.085
        children [
          Transform {
            children [
              Shape {
                appearance PBRAppearance {
                  baseColor 0.90 0.90 0.92
                  roughness 0.75
                  metalness 0.03
                }
                geometry Sphere { radius 0.022 }
              }
            ]
          }
          Transform {
            translation -0.100 -0.090 0
            rotation 0 0 1 -2.4088
            children [
              Transform {
                scale 0.79 0.24 0.20
                children [
                  Shape {
                    appearance PBRAppearance {
                      baseColor 0.97 0.97 0.98
                      roughness 0.70
                      metalness 0.02
                    }
                    geometry Sphere { radius 0.170 }
                  }
                ]
              }
            ]
          }
          Transform {
            translation -0.100 -0.090 0.020
            rotation 0 0 1 -2.4088
            children [
              Shape {
                appearance PBRAppearance {
                  baseColor 0.80 0.80 0.83
                  roughness 0.60
                  metalness 0.04
                }
                geometry Cylinder { radius 0.005 height 0.170 }
              }
            ]
          }
          HingeJoint {
            jointParameters HingeJointParameters {
              anchor -0.200 -0.180 0
              axis 0 0 1
            }
            device [
              RotationalMotor {
                name "left_knee"
                minPosition -1.80
                maxPosition 0.20
                maxTorque 220
                maxVelocity 4.8
              }
              PositionSensor {
                name "left_knee_sensor"
              }
            ]
            endPoint Solid {
              name "left_crus"
              translation -0.200 -0.180 0
              children [
                Shape {
                  appearance PBRAppearance {
                    baseColor 0.88 0.88 0.90
                    roughness 0.74
                    metalness 0.02
                  }
                  geometry Sphere { radius 0.020 }
                }
                Transform {
                  translation 0.090 -0.100 0
                  rotation 0 0 1 -0.8380
                  children [
                    Transform {
                      scale 0.79 0.22 0.19
                      children [
                        Shape {
                          appearance PBRAppearance {
                            baseColor 0.97 0.97 0.98
                            roughness 0.70
                            metalness 0.02
                          }
                          geometry Sphere { radius 0.170 }
                        }
                      ]
                    }
                  ]
                }
                Transform {
                  translation 0.090 -0.100 0.020
                  rotation 0 0 1 -0.8380
                  children [
                    Shape {
                      appearance PBRAppearance {
                        baseColor 0.80 0.80 0.83
                        roughness 0.60
                        metalness 0.04
                      }
                      geometry Cylinder { radius 0.005 height 0.165 }
                    }
                  ]
                }
                Transform {
                  translation 0.180 -0.200 0
                  children [
                    Shape {
                      appearance PBRAppearance {
                        baseColor 0.12 0.12 0.12
                        roughness 0.72
                        metalness 0.05
                      }
                      geometry Box { size 0.040 0.030 0.038 }
                    }
                  ]
                }
                HingeJoint {
                  jointParameters HingeJointParameters {
                    anchor 0.180 -0.200 0
                    axis 0 0 1
                  }
                  device [
                    RotationalMotor {
                      name "left_ankle"
                      minPosition -0.20
                      maxPosition 1.30
                      maxTorque 140
                      maxVelocity 5.4
                    }
                    PositionSensor {
                      name "left_ankle_sensor"
                    }
                  ]
                  endPoint DEF LEFT_PALM_SOLID Solid {
                    name "left_palm"
                    translation 0.180 -0.200 0
                    children [
                      Shape {
                        appearance PBRAppearance {
                          baseColor 0.10 0.10 0.10
                          roughness 0.70
                          metalness 0.08
                        }
                        geometry Box { size 0.038 0.030 0.034 }
                      }
                      DEF LEFT_PALM_SCALE Transform {
                        rotation 0 0 1 0.57
                        scale 1 1 1
                        children [
                          Shape {
                            appearance PBRAppearance {
                              baseColor 0.72 0.86 0.97
                              roughness 0.92
                              metalness 0
                              transparency 0.12
                            }
                            geometry IndexedFaceSet {
                              coord Coordinate {
                                point [
                                   0.000  0.000  0.004,
                                  -0.050  0.042  0.004,
                                  -0.180  0.060  0.004,
                                  -0.336  0.010  0.004,
                                  -0.180 -0.060  0.004,
                                  -0.050 -0.042  0.004,
                                   0.000  0.000 -0.004,
                                  -0.050  0.042 -0.004,
                                  -0.180  0.060 -0.004,
                                  -0.336  0.010 -0.004,
                                  -0.180 -0.060 -0.004,
                                  -0.050 -0.042 -0.004
                                ]
                              }
                              coordIndex [
                                0 1 2 3 4 5 -1
                                6 11 10 9 8 7 -1
                                0 6 7 1 -1
                                1 7 8 2 -1
                                2 8 9 3 -1
                                3 9 10 4 -1
                                4 10 11 5 -1
                                5 11 6 0 -1
                              ]
                            }
                          }
                          Transform {
                            translation -0.070 0.024 0
                            rotation 0 0 1 1.5708
                            children [
                              Shape {
                                appearance PBRAppearance {
                                  baseColor 0.55 0.65 0.72
                                  roughness 0.90
                                  metalness 0
                                }
                                geometry Cylinder { radius 0.0035 height 0.055 }
                              }
                            ]
                          }
                          Transform {
                            translation -0.170 0.010 0
                            rotation 0 0 1 1.300
                            children [
                              Shape {
                                appearance PBRAppearance {
                                  baseColor 0.55 0.65 0.72
                                  roughness 0.90
                                  metalness 0
                                }
                                geometry Cylinder { radius 0.0035 height 0.110 }
                              }
                            ]
                          }
                          Transform {
                            translation -0.260 -0.006 0
                            rotation 0 0 1 1.080
                            children [
                              Shape {
                                appearance PBRAppearance {
                                  baseColor 0.55 0.65 0.72
                                  roughness 0.90
                                  metalness 0
                                }
                                geometry Cylinder { radius 0.0035 height 0.125 }
                              }
                            ]
                          }
                        ]
                      }
                    ]
                    boundingObject Transform {
                      rotation 0 0 1 0.57
                      children [ Box { size 0.340 0.110 0.010 } ]
                    }
                    immersionProperties [
                      ImmersionProperties {
                        fluidName "water"
                        dragForceCoefficients 2.50 0.30 2.50
                        viscousResistanceForceCoefficient 95
                        viscousResistanceTorqueCoefficient 0.8
                      }
                    ]
                    physics Physics {
                      density -1
                      mass 0.30
                    }
                  }
                }
              ]
              boundingObject Transform {
                translation 0.090 -0.100 0
                rotation 0 0 1 -0.8380
                children [ Box { size 0.270 0.075 0.060 } ]
              }
              immersionProperties [
                ImmersionProperties {
                  fluidName "water"
                  dragForceCoefficients 0.95 0.38 1.05
                  viscousResistanceForceCoefficient 60
                  viscousResistanceTorqueCoefficient 1.9
                }
              ]
              physics Physics {
                density -1
                mass 0.95
              }
            }
          }
        ]
        boundingObject Transform {
          translation -0.100 -0.090 0
          rotation 0 0 1 -2.4088
          children [ Box { size 0.270 0.085 0.065 } ]
        }
        immersionProperties [
          ImmersionProperties {
            fluidName "water"
            dragForceCoefficients 0.85 0.30 0.95
            viscousResistanceForceCoefficient 55
            viscousResistanceTorqueCoefficient 1.6
          }
        ]
        physics Physics {
          density -1
          mass 1.20
        }
      }
    }

    HingeJoint {
      jointParameters HingeJointParameters {
        anchor 0.120 -0.150 0.085
        axis 0 0 1
      }
      device [
        RotationalMotor {
          name "right_hip"
          minPosition -0.80
          maxPosition 1.20
          maxTorque 260
          maxVelocity 4.0
        }
        PositionSensor {
          name "right_hip_sensor"
        }
      ]
      endPoint Solid {
        name "right_thigh"
        translation 0.120 -0.150 0.085
        children [
          Transform {
            children [
              Shape {
                appearance PBRAppearance {
                  baseColor 0.90 0.90 0.92
                  roughness 0.75
                  metalness 0.03
                }
                geometry Sphere { radius 0.022 }
              }
            ]
          }
          Transform {
            translation 0.100 -0.090 0
            rotation 0 0 1 -0.7328
            children [
              Transform {
                scale 0.79 0.24 0.20
                children [
                  Shape {
                    appearance PBRAppearance {
                      baseColor 0.97 0.97 0.98
                      roughness 0.70
                      metalness 0.02
                    }
                    geometry Sphere { radius 0.170 }
                  }
                ]
              }
            ]
          }
          Transform {
            translation 0.100 -0.090 0.020
            rotation 0 0 1 -0.7328
            children [
              Shape {
                appearance PBRAppearance {
                  baseColor 0.80 0.80 0.83
                  roughness 0.60
                  metalness 0.04
                }
                geometry Cylinder { radius 0.005 height 0.170 }
              }
            ]
          }
          HingeJoint {
            jointParameters HingeJointParameters {
              anchor 0.200 -0.180 0
              axis 0 0 1
            }
            device [
              RotationalMotor {
                name "right_knee"
                minPosition -0.20
                maxPosition 1.80
                maxTorque 220
                maxVelocity 4.8
              }
              PositionSensor {
                name "right_knee_sensor"
              }
            ]
            endPoint Solid {
              name "right_crus"
              translation 0.200 -0.180 0
              children [
                Shape {
                  appearance PBRAppearance {
                    baseColor 0.88 0.88 0.90
                    roughness 0.74
                    metalness 0.02
                  }
                  geometry Sphere { radius 0.020 }
                }
                Transform {
                  translation -0.090 -0.100 0
                  rotation 0 0 1 -2.3036
                  children [
                    Transform {
                      scale 0.79 0.22 0.19
                      children [
                        Shape {
                          appearance PBRAppearance {
                            baseColor 0.97 0.97 0.98
                            roughness 0.70
                            metalness 0.02
                          }
                          geometry Sphere { radius 0.170 }
                        }
                      ]
                    }
                  ]
                }
                Transform {
                  translation -0.090 -0.100 0.020
                  rotation 0 0 1 -2.3036
                  children [
                    Shape {
                      appearance PBRAppearance {
                        baseColor 0.80 0.80 0.83
                        roughness 0.60
                        metalness 0.04
                      }
                      geometry Cylinder { radius 0.005 height 0.165 }
                    }
                  ]
                }
                Transform {
                  translation -0.180 -0.200 0
                  children [
                    Shape {
                      appearance PBRAppearance {
                        baseColor 0.12 0.12 0.12
                        roughness 0.72
                        metalness 0.05
                      }
                      geometry Box { size 0.040 0.030 0.038 }
                    }
                  ]
                }
                HingeJoint {
                  jointParameters HingeJointParameters {
                    anchor -0.180 -0.200 0
                    axis 0 0 1
                  }
                  device [
                    RotationalMotor {
                      name "right_ankle"
                      minPosition -1.30
                      maxPosition 0.20
                      maxTorque 140
                      maxVelocity 5.4
                    }
                    PositionSensor {
                      name "right_ankle_sensor"
                    }
                  ]
                  endPoint DEF RIGHT_PALM_SOLID Solid {
                    name "right_palm"
                    translation -0.180 -0.200 0
                    children [
                      Shape {
                        appearance PBRAppearance {
                          baseColor 0.10 0.10 0.10
                          roughness 0.70
                          metalness 0.08
                        }
                        geometry Box { size 0.038 0.030 0.034 }
                      }
                      DEF RIGHT_PALM_SCALE Transform {
                        rotation 0 0 1 2.57
                        scale 1 1 1
                        children [
                          Shape {
                            appearance PBRAppearance {
                              baseColor 0.72 0.86 0.97
                              roughness 0.92
                              metalness 0
                              transparency 0.12
                            }
                            geometry IndexedFaceSet {
                              coord Coordinate {
                                point [
                                   0.000  0.000  0.004,
                                  -0.050  0.042  0.004,
                                  -0.180  0.060  0.004,
                                  -0.336  0.010  0.004,
                                  -0.180 -0.060  0.004,
                                  -0.050 -0.042  0.004,
                                   0.000  0.000 -0.004,
                                  -0.050  0.042 -0.004,
                                  -0.180  0.060 -0.004,
                                  -0.336  0.010 -0.004,
                                  -0.180 -0.060 -0.004,
                                  -0.050 -0.042 -0.004
                                ]
                              }
                              coordIndex [
                                0 1 2 3 4 5 -1
                                6 11 10 9 8 7 -1
                                0 6 7 1 -1
                                1 7 8 2 -1
                                2 8 9 3 -1
                                3 9 10 4 -1
                                4 10 11 5 -1
                                5 11 6 0 -1
                              ]
                            }
                          }
                          Transform {
                            translation -0.070 0.024 0
                            rotation 0 0 1 1.5708
                            children [
                              Shape {
                                appearance PBRAppearance {
                                  baseColor 0.55 0.65 0.72
                                  roughness 0.90
                                  metalness 0
                                }
                                geometry Cylinder { radius 0.0035 height 0.055 }
                              }
                            ]
                          }
                          Transform {
                            translation -0.170 0.010 0
                            rotation 0 0 1 1.300
                            children [
                              Shape {
                                appearance PBRAppearance {
                                  baseColor 0.55 0.65 0.72
                                  roughness 0.90
                                  metalness 0
                                }
                                geometry Cylinder { radius 0.0035 height 0.110 }
                              }
                            ]
                          }
                          Transform {
                            translation -0.260 -0.006 0
                            rotation 0 0 1 1.080
                            children [
                              Shape {
                                appearance PBRAppearance {
                                  baseColor 0.55 0.65 0.72
                                  roughness 0.90
                                  metalness 0
                                }
                                geometry Cylinder { radius 0.0035 height 0.125 }
                              }
                            ]
                          }
                        ]
                      }
                    ]
                    boundingObject Transform {
                      rotation 0 0 1 2.57
                      children [ Box { size 0.340 0.110 0.010 } ]
                    }
                    immersionProperties [
                      ImmersionProperties {
                        fluidName "water"
                        dragForceCoefficients 2.50 0.30 2.50
                        viscousResistanceForceCoefficient 95
                        viscousResistanceTorqueCoefficient 0.8
                      }
                    ]
                    physics Physics {
                      density -1
                      mass 0.30
                    }
                  }
                }
              ]
              boundingObject Transform {
                translation -0.090 -0.100 0
                rotation 0 0 1 -2.3036
                children [ Box { size 0.270 0.075 0.060 } ]
              }
              immersionProperties [
                ImmersionProperties {
                  fluidName "water"
                  dragForceCoefficients 0.95 0.38 1.05
                  viscousResistanceForceCoefficient 60
                  viscousResistanceTorqueCoefficient 1.9
                }
              ]
              physics Physics {
                density -1
                mass 0.95
              }
            }
          }
        ]
        boundingObject Transform {
          translation 0.100 -0.090 0
          rotation 0 0 1 -0.7328
          children [ Box { size 0.270 0.085 0.065 } ]
        }
        immersionProperties [
          ImmersionProperties {
            fluidName "water"
            dragForceCoefficients 0.85 0.30 0.95
            viscousResistanceForceCoefficient 55
            viscousResistanceTorqueCoefficient 1.6
          }
        ]
        physics Physics {
          density -1
          mass 1.20
        }
      }
    }
  ]
  boundingObject Sphere {
    radius 0.170
  }
  physics Physics {
    density -1
    mass 7.20
  }
}
